<?xml version="1.0" ?>
<mujoco model="example_bot">
  <worldbody>
    <body name="base_link" pos="0.0 0.0 0.1">
      <inertial pos="0 0 0" mass="5.0" ixx="0.1" iyy="0.1" izz="0.05" ixy="0.0" ixz="0.0" iyz="0.0"/>
      <geom type="mesh" mesh="meshes/base.stl"/>
      <geom type="mesh" mesh="meshes/base_col.stl"/>
      <joint name="joint1" type="hinge" axis="0 0 1"/>
    </body>
    <body name="link1" pos="0.0 0.0 0.1">
      <inertial pos="0 0 0" mass="1.0" ixx="0.01" iyy="0.01" izz="0.005" ixy="0.0" ixz="0.0" iyz="0.0"/>
    </body>
  </worldbody>
  <actuator>
    <motor name="motor_joint1" joint="joint1" gear="100" ctrlrange="-5.0 5.0"/>
  </actuator>
  <default>
    <geom friction="0.85 0.85 0.0"/>
  </default>
</mujoco>
